Workbook

Sheet Dashboard
A1: Dashboard ค่าใช้จ่าย รายรับ และ VAT รายเดือน
A3: ปี | B3: =Settings!B5 | D3: VAT สุทธิทั้งปี | E3: =Monthly_VAT!G17
A4: รายรับก่อน VAT | B4: =SUM(Monthly_VAT!B4:B15) | D4: เดือนที่ VAT ต้องจ่ายสูงสุด | E4: =INDEX(Monthly_VAT!A4:A15,MATCH(MAX(Monthly_VAT!G4:G15),Monthly_VAT!G4:G15,0))
A5: ค่าใช้จ่ายก่อน VAT | B5: =SUM(Monthly_VAT!D4:D15) | D5: สถานะรวม | E5: =IF(E3>0,"ต้องจ่าย",IF(E3<0,"ขอคืน/เครดิต","ไม่มี VAT สุทธิ"))
A6: รายรับสุทธิ | B6: =SUM(Monthly_VAT!F4:F15)
A7: ภาษีขาย | B7: =SUM(Monthly_VAT!C4:C15)
A8: ภาษีซื้อ | B8: =SUM(Monthly_VAT!E4:E15)
A10: เดือน | B10: รายรับก่อน VAT | C10: ค่าใช้จ่ายก่อน VAT | D10: รายรับสุทธิ | E10: ภาษีขาย | F10: ภาษีซื้อ | G10: VAT สุทธิ | P10: เดือน | Q10: รายรับก่อน VAT | R10: ค่าใช้จ่ายก่อน VAT | S10: รายรับสุทธิ | U10: เดือน | V10: VAT สุทธิ
A11: =Monthly_VAT!A4 | B11: =Monthly_VAT!B4 | C11: =Monthly_VAT!D4 | D11: =Monthly_VAT!F4 | E11: =Monthly_VAT!C4 | F11: =Monthly_VAT!E4 | G11: =Monthly_VAT!G4 | P11: Jan 2026 | Q11: =Monthly_VAT!B4 | R11: =Monthly_VAT!D4 | S11: =Monthly_VAT!F4 | U11: Jan 2026 | V11: =Monthly_VAT!G4
A12: =Monthly_VAT!A5 | B12: =Monthly_VAT!B5 | C12: =Monthly_VAT!D5 | D12: =Monthly_VAT!F5 | E12: =Monthly_VAT!C5 | F12: =Monthly_VAT!E5 | G12: =Monthly_VAT!G5 | P12: Feb 2026 | Q12: =Monthly_VAT!B5 | R12: =Monthly_VAT!D5 | S12: =Monthly_VAT!F5 | U12: Feb 2026 | V12: =Monthly_VAT!G5
A13: =Monthly_VAT!A6 | B13: =Monthly_VAT!B6 | C13: =Monthly_VAT!D6 | D13: =Monthly_VAT!F6 | E13: =Monthly_VAT!C6 | F13: =Monthly_VAT!E6 | G13: =Monthly_VAT!G6 | P13: Mar 2026 | Q13: =Monthly_VAT!B6 | R13: =Monthly_VAT!D6 | S13: =Monthly_VAT!F6 | U13: Mar 2026 | V13: =Monthly_VAT!G6
A14: =Monthly_VAT!A7 | B14: =Monthly_VAT!B7 | C14: =Monthly_VAT!D7 | D14: =Monthly_VAT!F7 | E14: =Monthly_VAT!C7 | F14: =Monthly_VAT!E7 | G14: =Monthly_VAT!G7 | P14: Apr 2026 | Q14: =Monthly_VAT!B7 | R14: =Monthly_VAT!D7 | S14: =Monthly_VAT!F7 | U14: Apr 2026 | V14: =Monthly_VAT!G7
A15: =Monthly_VAT!A8 | B15: =Monthly_VAT!B8 | C15: =Monthly_VAT!D8 | D15: =Monthly_VAT!F8 | E15: =Monthly_VAT!C8 | F15: =Monthly_VAT!E8 | G15: =Monthly_VAT!G8 | P15: May 2026 | Q15: =Monthly_VAT!B8 | R15: =Monthly_VAT!D8 | S15: =Monthly_VAT!F8 | U15: May 2026 | V15: =Monthly_VAT!G8
A16: =Monthly_VAT!A9 | B16: =Monthly_VAT!B9 | C16: =Monthly_VAT!D9 | D16: =Monthly_VAT!F9 | E16: =Monthly_VAT!C9 | F16: =Monthly_VAT!E9 | G16: =Monthly_VAT!G9 | P16: Jun 2026 | Q16: =Monthly_VAT!B9 | R16: =Monthly_VAT!D9 | S16: =Monthly_VAT!F9 | U16: Jun 2026 | V16: =Monthly_VAT!G9
A17: =Monthly_VAT!A10 | B17: =Monthly_VAT!B10 | C17: =Monthly_VAT!D10 | D17: =Monthly_VAT!F10 | E17: =Monthly_VAT!C10 | F17: =Monthly_VAT!E10 | G17: =Monthly_VAT!G10 | P17: Jul 2026 | Q17: =Monthly_VAT!B10 | R17: =Monthly_VAT!D10 | S17: =Monthly_VAT!F10 | U17: Jul 2026 | V17: =Monthly_VAT!G10
A18: =Monthly_VAT!A11 | B18: =Monthly_VAT!B11 | C18: =Monthly_VAT!D11 | D18: =Monthly_VAT!F11 | E18: =Monthly_VAT!C11 | F18: =Monthly_VAT!E11 | G18: =Monthly_VAT!G11 | P18: Aug 2026 | Q18: =Monthly_VAT!B11 | R18: =Monthly_VAT!D11 | S18: =Monthly_VAT!F11 | U18: Aug 2026 | V18: =Monthly_VAT!G11
A19: =Monthly_VAT!A12 | B19: =Monthly_VAT!B12 | C19: =Monthly_VAT!D12 | D19: =Monthly_VAT!F12 | E19: =Monthly_VAT!C12 | F19: =Monthly_VAT!E12 | G19: =Monthly_VAT!G12 | P19: Sep 2026 | Q19: =Monthly_VAT!B12 | R19: =Monthly_VAT!D12 | S19: =Monthly_VAT!F12 | U19: Sep 2026 | V19: =Monthly_VAT!G12
A20: =Monthly_VAT!A13 | B20: =Monthly_VAT!B13 | C20: =Monthly_VAT!D13 | D20: =Monthly_VAT!F13 | E20: =Monthly_VAT!C13 | F20: =Monthly_VAT!E13 | G20: =Monthly_VAT!G13 | P20: Oct 2026 | Q20: =Monthly_VAT!B13 | R20: =Monthly_VAT!D13 | S20: =Monthly_VAT!F13 | U20: Oct 2026 | V20: =Monthly_VAT!G13
A21: =Monthly_VAT!A14 | B21: =Monthly_VAT!B14 | C21: =Monthly_VAT!D14 | D21: =Monthly_VAT!F14 | E21: =Monthly_VAT!C14 | F21: =Monthly_VAT!E14 | G21: =Monthly_VAT!G14 | P21: Nov 2026 | Q21: =Monthly_VAT!B14 | R21: =Monthly_VAT!D14 | S21: =Monthly_VAT!F14 | U21: Nov 2026 | V21: =Monthly_VAT!G14
A22: =Monthly_VAT!A15 | B22: =Monthly_VAT!B15 | C22: =Monthly_VAT!D15 | D22: =Monthly_VAT!F15 | E22: =Monthly_VAT!C15 | F22: =Monthly_VAT!E15 | G22: =Monthly_VAT!G15 | P22: Dec 2026 | Q22: =Monthly_VAT!B15 | R22: =Monthly_VAT!D15 | S22: =Monthly_VAT!F15 | U22: Dec 2026 | V22: =Monthly_VAT!G15

Sheet Transactions_12M
A1: Revenue + Expenses Entry - กรอกรายรับ/ค่าใช้จ่ายทีละรายการ แยกรายเดือน
A3: January 2026 / เดือน Jan
A4: วันที่ | B4: ประเภท | C4: เลขที่เอกสาร | D4: ลูกค้า/ผู้ขาย | E4: รายละเอียด | F4: หมวด | G4: ยอดก่อน VAT | H4: อัตรา VAT | I4: VAT | J4: ยอดรวม | K4: รับเงิน/ขอคืน VAT? | L4: เดือน | M4: ไฟล์เอกสาร | N4: OCR Confidence | O4: รายรับก่อน VAT | P4: ค่าใช้จ่ายก่อน VAT | Q4: หมายเหตุ | R4: ประเภทเอกสาร
H5: =IF(A5="","",Settings!$B$4) | I5: =IF(G5="","",IF(OR(B5="Revenue",K5="Yes"),ROUND(G5*H5,2),0)) | J5: =IF(G5="","",G5+ROUND(G5*H5,2)) | L5: =IF(A5="","",DATE(YEAR(A5),MONTH(A5),1)) | O5: =IF(B5="Revenue",G5,0) | P5: =IF(B5="Expense",G5,0)
H6: =IF(A6="","",Settings!$B$4) | I6: =IF(G6="","",IF(OR(B6="Revenue",K6="Yes"),ROUND(G6*H6,2),0)) | J6: =IF(G6="","",G6+ROUND(G6*H6,2)) | L6: =IF(A6="","",DATE(YEAR(A6),MONTH(A6),1)) | O6: =IF(B6="Revenue",G6,0) | P6: =IF(B6="Expense",G6,0)
H7: =IF(A7="","",Settings!$B$4) | I7: =IF(G7="","",IF(OR(B7="Revenue",K7="Yes"),ROUND(G7*H7,2),0)) | J7: =IF(G7="","",G7+ROUND(G7*H7,2)) | L7: =IF(A7="","",DATE(YEAR(A7),MONTH(A7),1)) | O7: =IF(B7="Revenue",G7,0) | P7: =IF(B7="Expense",G7,0)
H8: =IF(A8="","",Settings!$B$4) | I8: =IF(G8="","",IF(OR(B8="Revenue",K8="Yes"),ROUND(G8*H8,2),0)) | J8: =IF(G8="","",G8+ROUND(G8*H8,2)) | L8: =IF(A8="","",DATE(YEAR(A8),MONTH(A8),1)) | O8: =IF(B8="Revenue",G8,0) | P8: =IF(B8="Expense",G8,0)
H9: =IF(A9="","",Settings!$B$4) | I9: =IF(G9="","",IF(OR(B9="Revenue",K9="Yes"),ROUND(G9*H9,2),0)) | J9: =IF(G9="","",G9+ROUND(G9*H9,2)) | L9: =IF(A9="","",DATE(YEAR(A9),MONTH(A9),1)) | O9: =IF(B9="Revenue",G9,0) | P9: =IF(B9="Expense",G9,0)
H10: =IF(A10="","",Settings!$B$4) | I10: =IF(G10="","",IF(OR(B10="Revenue",K10="Yes"),ROUND(G10*H10,2),0)) | J10: =IF(G10="","",G10+ROUND(G10*H10,2)) | L10: =IF(A10="","",DATE(YEAR(A10),MONTH(A10),1)) | O10: =IF(B10="Revenue",G10,0) | P10: =IF(B10="Expense",G10,0)
H11: =IF(A11="","",Settings!$B$4) | I11: =IF(G11="","",IF(OR(B11="Revenue",K11="Yes"),ROUND(G11*H11,2),0)) | J11: =IF(G11="","",G11+ROUND(G11*H11,2)) | L11: =IF(A11="","",DATE(YEAR(A11),MONTH(A11),1)) | O11: =IF(B11="Revenue",G11,0) | P11: =IF(B11="Expense",G11,0)
H12: =IF(A12="","",Settings!$B$4) | I12: =IF(G12="","",IF(OR(B12="Revenue",K12="Yes"),ROUND(G12*H12,2),0)) | J12: =IF(G12="","",G12+ROUND(G12*H12,2)) | L12: =IF(A12="","",DATE(YEAR(A12),MONTH(A12),1)) | O12: =IF(B12="Revenue",G12,0) | P12: =IF(B12="Expense",G12,0)
H13: =IF(A13="","",Settings!$B$4) | I13: =IF(G13="","",IF(OR(B13="Revenue",K13="Yes"),ROUND(G13*H13,2),0)) | J13: =IF(G13="","",G13+ROUND(G13*H13,2)) | L13: =IF(A13="","",DATE(YEAR(A13),MONTH(A13),1)) | O13: =IF(B13="Revenue",G13,0) | P13: =IF(B13="Expense",G13,0)
H14: =IF(A14="","",Settings!$B$4) | I14: =IF(G14="","",IF(OR(B14="Revenue",K14="Yes"),ROUND(G14*H14,2),0)) | J14: =IF(G14="","",G14+ROUND(G14*H14,2)) | L14: =IF(A14="","",DATE(YEAR(A14),MONTH(A14),1)) | O14: =IF(B14="Revenue",G14,0) | P14: =IF(B14="Expense",G14,0)
H15: =IF(A15="","",Settings!$B$4) | I15: =IF(G15="","",IF(OR(B15="Revenue",K15="Yes"),ROUND(G15*H15,2),0)) | J15: =IF(G15="","",G15+ROUND(G15*H15,2)) | L15: =IF(A15="","",DATE(YEAR(A15),MONTH(A15),1)) | O15: =IF(B15="Revenue",G15,0) | P15: =IF(B15="Expense",G15,0)
H16: =IF(A16="","",Settings!$B$4) | I16: =IF(G16="","",IF(OR(B16="Revenue",K16="Yes"),ROUND(G16*H16,2),0)) | J16: =IF(G16="","",G16+ROUND(G16*H16,2)) | L16: =IF(A16="","",DATE(YEAR(A16),MONTH(A16),1)) | O16: =IF(B16="Revenue",G16,0) | P16: =IF(B16="Expense",G16,0)
... H34: =IF(A34="","",Settings!$B$4) | I34: =IF(G34="","",IF(OR(B34="Revenue",K34="Yes"),ROUND(G34*H34,2),0)) | J34: =IF(G34="","",G34+ROUND(G34*H34,2)) | L34: =IF(A34="","",DATE(YEAR(A34),MONTH(A34),1)) | O34: =IF(B34="Revenue",G34,0) | P34: =IF(B34="Expense",G34,0)
A36: February 2026 / เดือน Feb
A37: วันที่ | B37: ประเภท | C37: เลขที่เอกสาร | D37: ลูกค้า/ผู้ขาย | E37: รายละเอียด | F37: หมวด | G37: ยอดก่อน VAT | H37: อัตรา VAT | I37: VAT | J37: ยอดรวม | K37: รับเงิน/ขอคืน VAT? | L37: เดือน | M37: ไฟล์เอกสาร | N37: OCR Confidence | O37: รายรับก่อน VAT | P37: ค่าใช้จ่ายก่อน VAT | Q37: หมายเหตุ | R37: ประเภทเอกสาร
H38: =IF(A38="","",Settings!$B$4) | I38: =IF(G38="","",IF(OR(B38="Revenue",K38="Yes"),ROUND(G38*H38,2),0)) | J38: =IF(G38="","",G38+ROUND(G38*H38,2)) | L38: =IF(A38="","",DATE(YEAR(A38),MONTH(A38),1)) | O38: =IF(B38="Revenue",G38,0) | P38: =IF(B38="Expense",G38,0)
H39: =IF(A39="","",Settings!$B$4) | I39: =IF(G39="","",IF(OR(B39="Revenue",K39="Yes"),ROUND(G39*H39,2),0)) | J39: =IF(G39="","",G39+ROUND(G39*H39,2)) | L39: =IF(A39="","",DATE(YEAR(A39),MONTH(A39),1)) | O39: =IF(B39="Revenue",G39,0) | P39: =IF(B39="Expense",G39,0)
H40: =IF(A40="","",Settings!$B$4) | I40: =IF(G40="","",IF(OR(B40="Revenue",K40="Yes"),ROUND(G40*H40,2),0)) | J40: =IF(G40="","",G40+ROUND(G40*H40,2)) | L40: =IF(A40="","",DATE(YEAR(A40),MONTH(A40),1)) | O40: =IF(B40="Revenue",G40,0) | P40: =IF(B40="Expense",G40,0)
H41: =IF(A41="","",Settings!$B$4) | I41: =IF(G41="","",IF(OR(B41="Revenue",K41="Yes"),ROUND(G41*H41,2),0)) | J41: =IF(G41="","",G41+ROUND(G41*H41,2)) | L41: =IF(A41="","",DATE(YEAR(A41),MONTH(A41),1)) | O41: =IF(B41="Revenue",G41,0) | P41: =IF(B41="Expense",G41,0)
H42: =IF(A42="","",Settings!$B$4) | I42: =IF(G42="","",IF(OR(B42="Revenue",K42="Yes"),ROUND(G42*H42,2),0)) | J42: =IF(G42="","",G42+ROUND(G42*H42,2)) | L42: =IF(A42="","",DATE(YEAR(A42),MONTH(A42),1)) | O42: =IF(B42="Revenue",G42,0) | P42: =IF(B42="Expense",G42,0)
H43: =IF(A43="","",Settings!$B$4) | I43: =IF(G43="","",IF(OR(B43="Revenue",K43="Yes"),ROUND(G43*H43,2),0)) | J43: =IF(G43="","",G43+ROUND(G43*H43,2)) | L43: =IF(A43="","",DATE(YEAR(A43),MONTH(A43),1)) | O43: =IF(B43="Revenue",G43,0) | P43: =IF(B43="Expense",G43,0)
H44: =IF(A44="","",Settings!$B$4) | I44: =IF(G44="","",IF(OR(B44="Revenue",K44="Yes"),ROUND(G44*H44,2),0)) | J44: =IF(G44="","",G44+ROUND(G44*H44,2)) | L44: =IF(A44="","",DATE(YEAR(A44),MONTH(A44),1)) | O44: =IF(B44="Revenue",G44,0) | P44: =IF(B44="Expense",G44,0)
H45: =IF(A45="","",Settings!$B$4) | I45: =IF(G45="","",IF(OR(B45="Revenue",K45="Yes"),ROUND(G45*H45,2),0)) | J45: =IF(G45="","",G45+ROUND(G45*H45,2)) | L45: =IF(A45="","",DATE(YEAR(A45),MONTH(A45),1)) | O45: =IF(B45="Revenue",G45,0) | P45: =IF(B45="Expense",G45,0)
H46: =IF(A46="","",Settings!$B$4) | I46: =IF(G46="","",IF(OR(B46="Revenue",K46="Yes"),ROUND(G46*H46,2),0)) | J46: =IF(G46="","",G46+ROUND(G46*H46,2)) | L46: =IF(A46="","",DATE(YEAR(A46),MONTH(A46),1)) | O46: =IF(B46="Revenue",G46,0) | P46: =IF(B46="Expense",G46,0)
H47: =IF(A47="","",Settings!$B$4) | I47: =IF(G47="","",IF(OR(B47="Revenue",K47="Yes"),ROUND(G47*H47,2),0)) | J47: =IF(G47="","",G47+ROUND(G47*H47,2)) | L47: =IF(A47="","",DATE(YEAR(A47),MONTH(A47),1)) | O47: =IF(B47="Revenue",G47,0) | P47: =IF(B47="Expense",G47,0)
H48: =IF(A48="","",Settings!$B$4) | I48: =IF(G48="","",IF(OR(B48="Revenue",K48="Yes"),ROUND(G48*H48,2),0)) | J48: =IF(G48="","",G48+ROUND(G48*H48,2)) | L48: =IF(A48="","",DATE(YEAR(A48),MONTH(A48),1)) | O48: =IF(B48="Revenue",G48,0) | P48: =IF(B48="Expense",G48,0)
H49: =IF(A49="","",Settings!$B$4) | I49: =IF(G49="","",IF(OR(B49="Revenue",K49="Yes"),ROUND(G49*H49,2),0)) | J49: =IF(G49="","",G49+ROUND(G49*H49,2)) | L49: =IF(A49="","",DATE(YEAR(A49),MONTH(A49),1)) | O49: =IF(B49="Revenue",G49,0) | P49: =IF(B49="Expense",G49,0)
... H67: =IF(A67="","",Settings!$B$4) | I67: =IF(G67="","",IF(OR(B67="Revenue",K67="Yes"),ROUND(G67*H67,2),0)) | J67: =IF(G67="","",G67+ROUND(G67*H67,2)) | L67: =IF(A67="","",DATE(YEAR(A67),MONTH(A67),1)) | O67: =IF(B67="Revenue",G67,0) | P67: =IF(B67="Expense",G67,0)
A69: March 2026 / เดือน Mar
A70: วันที่ | B70: ประเภท | C70: เลขที่เอกสาร | D70: ลูกค้า/ผู้ขาย | E70: รายละเอียด | F70: หมวด | G70: ยอดก่อน VAT | H70: อัตรา VAT | I70: VAT | J70: ยอดรวม | K70: รับเงิน/ขอคืน VAT? | L70: เดือน | M70: ไฟล์เอกสาร | N70: OCR Confidence | O70: รายรับก่อน VAT | P70: ค่าใช้จ่ายก่อน VAT | Q70: หมายเหตุ | R70: ประเภทเอกสาร
H71: =IF(A71="","",Settings!$B$4) | I71: =IF(G71="","",IF(OR(B71="Revenue",K71="Yes"),ROUND(G71*H71,2),0)) | J71: =IF(G71="","",G71+ROUND(G71*H71,2)) | L71: =IF(A71="","",DATE(YEAR(A71),MONTH(A71),1)) | O71: =IF(B71="Revenue",G71,0) | P71: =IF(B71="Expense",G71,0)
H72: =IF(A72="","",Settings!$B$4) | I72: =IF(G72="","",IF(OR(B72="Revenue",K72="Yes"),ROUND(G72*H72,2),0)) | J72: =IF(G72="","",G72+ROUND(G72*H72,2)) | L72: =IF(A72="","",DATE(YEAR(A72),MONTH(A72),1)) | O72: =IF(B72="Revenue",G72,0) | P72: =IF(B72="Expense",G72,0)
H73: =IF(A73="","",Settings!$B$4) | I73: =IF(G73="","",IF(OR(B73="Revenue",K73="Yes"),ROUND(G73*H73,2),0)) | J73: =IF(G73="","",G73+ROUND(G73*H73,2)) | L73: =IF(A73="","",DATE(YEAR(A73),MONTH(A73),1)) | O73: =IF(B73="Revenue",G73,0) | P73: =IF(B73="Expense",G73,0)
H74: =IF(A74="","",Settings!$B$4) | I74: =IF(G74="","",IF(OR(B74="Revenue",K74="Yes"),ROUND(G74*H74,2),0)) | J74: =IF(G74="","",G74+ROUND(G74*H74,2)) | L74: =IF(A74="","",DATE(YEAR(A74),MONTH(A74),1)) | O74: =IF(B74="Revenue",G74,0) | P74: =IF(B74="Expense",G74,0)
H75: =IF(A75="","",Settings!$B$4) | I75: =IF(G75="","",IF(OR(B75="Revenue",K75="Yes"),ROUND(G75*H75,2),0)) | J75: =IF(G75="","",G75+ROUND(G75*H75,2)) | L75: =IF(A75="","",DATE(YEAR(A75),MONTH(A75),1)) | O75: =IF(B75="Revenue",G75,0) | P75: =IF(B75="Expense",G75,0)
H76: =IF(A76="","",Settings!$B$4) | I76: =IF(G76="","",IF(OR(B76="Revenue",K76="Yes"),ROUND(G76*H76,2),0)) | J76: =IF(G76="","",G76+ROUND(G76*H76,2)) | L76: =IF(A76="","",DATE(YEAR(A76),MONTH(A76),1)) | O76: =IF(B76="Revenue",G76,0) | P76: =IF(B76="Expense",G76,0)
H77: =IF(A77="","",Settings!$B$4) | I77: =IF(G77="","",IF(OR(B77="Revenue",K77="Yes"),ROUND(G77*H77,2),0)) | J77: =IF(G77="","",G77+ROUND(G77*H77,2)) | L77: =IF(A77="","",DATE(YEAR(A77),MONTH(A77),1)) | O77: =IF(B77="Revenue",G77,0) | P77: =IF(B77="Expense",G77,0)
...

Sheet Revenue
A1: ตารางรายรับ / ภาษีขาย
A3: วันที่ | B3: เลขที่ใบกำกับ | C3: ลูกค้า | D3: รายละเอียด | E3: ยอดก่อน VAT | F3: อัตรา VAT | G3: ภาษีขาย | H3: ยอดรวม | I3: รับเงินแล้ว? | J3: เดือน | K3: หมายเหตุ
F4: =IF(A4="","",Settings!$B$4) | G4: =IF(E4="","",ROUND(E4*F4,2)) | H4: =IF(E4="","",E4+G4) | J4: =IF(A4="","",DATE(YEAR(A4),MONTH(A4),1))
F5: =IF(A5="","",Settings!$B$4) | G5: =IF(E5="","",ROUND(E5*F5,2)) | H5: =IF(E5="","",E5+G5) | J5: =IF(A5="","",DATE(YEAR(A5),MONTH(A5),1))
F6: =IF(A6="","",Settings!$B$4) | G6: =IF(E6="","",ROUND(E6*F6,2)) | H6: =IF(E6="","",E6+G6) | J6: =IF(A6="","",DATE(YEAR(A6),MONTH(A6),1))
F7: =IF(A7="","",Settings!$B$4) | G7: =IF(E7="","",ROUND(E7*F7,2)) | H7: =IF(E7="","",E7+G7) | J7: =IF(A7="","",DATE(YEAR(A7),MONTH(A7),1))
F8: =IF(A8="","",Settings!$B$4) | G8: =IF(E8="","",ROUND(E8*F8,2)) | H8: =IF(E8="","",E8+G8) | J8: =IF(A8="","",DATE(YEAR(A8),MONTH(A8),1))
F9: =IF(A9="","",Settings!$B$4) | G9: =IF(E9="","",ROUND(E9*F9,2)) | H9: =IF(E9="","",E9+G9) | J9: =IF(A9="","",DATE(YEAR(A9),MONTH(A9),1))
F10: =IF(A10="","",Settings!$B$4) | G10: =IF(E10="","",ROUND(E10*F10,2)) | H10: =IF(E10="","",E10+G10) | J10: =IF(A10="","",DATE(YEAR(A10),MONTH(A10),1))
F11: =IF(A11="","",Settings!$B$4) | G11: =IF(E11="","",ROUND(E11*F11,2)) | H11: =IF(E11="","",E11+G11) | J11: =IF(A11="","",DATE(YEAR(A11),MONTH(A11),1))
F12: =IF(A12="","",Settings!$B$4) | G12: =IF(E12="","",ROUND(E12*F12,2)) | H12: =IF(E12="","",E12+G12) | J12: =IF(A12="","",DATE(YEAR(A12),MONTH(A12),1))
F13: =IF(A13="","",Settings!$B$4) | G13: =IF(E13="","",ROUND(E13*F13,2)) | H13: =IF(E13="","",E13+G13) | J13: =IF(A13="","",DATE(YEAR(A13),MONTH(A13),1))
F14: =IF(A14="","",Settings!$B$4) | G14: =IF(E14="","",ROUND(E14*F14,2)) | H14: =IF(E14="","",E14+G14) | J14: =IF(A14="","",DATE(YEAR(A14),MONTH(A14),1))
F15: =IF(A15="","",Settings!$B$4) | G15: =IF(E15="","",ROUND(E15*F15,2)) | H15: =IF(E15="","",E15+G15) | J15: =IF(A15="","",DATE(YEAR(A15),MONTH(A15),1))
... F203: =IF(A203="","",Settings!$B$4) | G203: =IF(E203="","",ROUND(E203*F203,2)) | H203: =IF(E203="","",E203+G203) | J203: =IF(A203="","",DATE(YEAR(A203),MONTH(A203),1))

Sheet Revenue_12M
A1: Revenue Entry by Month - บันทึกรายรับรายรายการครบ 12 เดือน
A3: January 2026 / เดือน Jan
A4: วันที่ | B4: เลขที่ใบกำกับ | C4: ลูกค้า | D4: รายละเอียด | E4: ยอดก่อน VAT | F4: อัตรา VAT | G4: ภาษีขาย | H4: ยอดรวม | I4: รับเงินแล้ว? | J4: เดือน | K4: หมายเหตุ
F5: =IF(A5="","",Settings!$B$4) | G5: =IF(E5="","",ROUND(E5*F5,2)) | H5: =IF(E5="","",E5+G5) | J5: =IF(A5="","",DATE(YEAR(A5),MONTH(A5),1))
F6: =IF(A6="","",Settings!$B$4) | G6: =IF(E6="","",ROUND(E6*F6,2)) | H6: =IF(E6="","",E6+G6) | J6: =IF(A6="","",DATE(YEAR(A6),MONTH(A6),1))
F7: =IF(A7="","",Settings!$B$4) | G7: =IF(E7="","",ROUND(E7*F7,2)) | H7: =IF(E7="","",E7+G7) | J7: =IF(A7="","",DATE(YEAR(A7),MONTH(A7),1))
F8: =IF(A8="","",Settings!$B$4) | G8: =IF(E8="","",ROUND(E8*F8,2)) | H8: =IF(E8="","",E8+G8) | J8: =IF(A8="","",DATE(YEAR(A8),MONTH(A8),1))
F9: =IF(A9="","",Settings!$B$4) | G9: =IF(E9="","",ROUND(E9*F9,2)) | H9: =IF(E9="","",E9+G9) | J9: =IF(A9="","",DATE(YEAR(A9),MONTH(A9),1))
F10: =IF(A10="","",Settings!$B$4) | G10: =IF(E10="","",ROUND(E10*F10,2)) | H10: =IF(E10="","",E10+G10) | J10: =IF(A10="","",DATE(YEAR(A10),MONTH(A10),1))
F11: =IF(A11="","",Settings!$B$4) | G11: =IF(E11="","",ROUND(E11*F11,2)) | H11: =IF(E11="","",E11+G11) | J11: =IF(A11="","",DATE(YEAR(A11),MONTH(A11),1))
F12: =IF(A12="","",Settings!$B$4) | G12: =IF(E12="","",ROUND(E12*F12,2)) | H12: =IF(E12="","",E12+G12) | J12: =IF(A12="","",DATE(YEAR(A12),MONTH(A12),1))
F13: =IF(A13="","",Settings!$B$4) | G13: =IF(E13="","",ROUND(E13*F13,2)) | H13: =IF(E13="","",E13+G13) | J13: =IF(A13="","",DATE(YEAR(A13),MONTH(A13),1))
F14: =IF(A14="","",Settings!$B$4) | G14: =IF(E14="","",ROUND(E14*F14,2)) | H14: =IF(E14="","",E14+G14) | J14: =IF(A14="","",DATE(YEAR(A14),MONTH(A14),1))
F15: =IF(A15="","",Settings!$B$4) | G15: =IF(E15="","",ROUND(E15*F15,2)) | H15: =IF(E15="","",E15+G15) | J15: =IF(A15="","",DATE(YEAR(A15),MONTH(A15),1))
F16: =IF(A16="","",Settings!$B$4) | G16: =IF(E16="","",ROUND(E16*F16,2)) | H16: =IF(E16="","",E16+G16) | J16: =IF(A16="","",DATE(YEAR(A16),MONTH(A16),1))
... F24: =IF(A24="","",Settings!$B$4) | G24: =IF(E24="","",ROUND(E24*F24,2)) | H24: =IF(E24="","",E24+G24) | J24: =IF(A24="","",DATE(YEAR(A24),MONTH(A24),1))
A26: February 2026 / เดือน Feb
A27: วันที่ | B27: เลขที่ใบกำกับ | C27: ลูกค้า | D27: รายละเอียด | E27: ยอดก่อน VAT | F27: อัตรา VAT | G27: ภาษีขาย | H27: ยอดรวม | I27: รับเงินแล้ว? | J27: เดือน | K27: หมายเหตุ
F28: =IF(A28="","",Settings!$B$4) | G28: =IF(E28="","",ROUND(E28*F28,2)) | H28: =IF(E28="","",E28+G28) | J28: =IF(A28="","",DATE(YEAR(A28),MONTH(A28),1))
F29: =IF(A29="","",Settings!$B$4) | G29: =IF(E29="","",ROUND(E29*F29,2)) | H29: =IF(E29="","",E29+G29) | J29: =IF(A29="","",DATE(YEAR(A29),MONTH(A29),1))
F30: =IF(A30="","",Settings!$B$4) | G30: =IF(E30="","",ROUND(E30*F30,2)) | H30: =IF(E30="","",E30+G30) | J30: =IF(A30="","",DATE(YEAR(A30),MONTH(A30),1))
F31: =IF(A31="","",Settings!$B$4) | G31: =IF(E31="","",ROUND(E31*F31,2)) | H31: =IF(E31="","",E31+G31) | J31: =IF(A31="","",DATE(YEAR(A31),MONTH(A31),1))
F32: =IF(A32="","",Settings!$B$4) | G32: =IF(E32="","",ROUND(E32*F32,2)) | H32: =IF(E32="","",E32+G32) | J32: =IF(A32="","",DATE(YEAR(A32),MONTH(A32),1))
F33: =IF(A33="","",Settings!$B$4) | G33: =IF(E33="","",ROUND(E33*F33,2)) | H33: =IF(E33="","",E33+G33) | J33: =IF(A33="","",DATE(YEAR(A33),MONTH(A33),1))
F34: =IF(A34="","",Settings!$B$4) | G34: =IF(E34="","",ROUND(E34*F34,2)) | H34: =IF(E34="","",E34+G34) | J34: =IF(A34="","",DATE(YEAR(A34),MONTH(A34),1))
F35: =IF(A35="","",Settings!$B$4) | G35: =IF(E35="","",ROUND(E35*F35,2)) | H35: =IF(E35="","",E35+G35) | J35: =IF(A35="","",DATE(YEAR(A35),MONTH(A35),1))
F36: =IF(A36="","",Settings!$B$4) | G36: =IF(E36="","",ROUND(E36*F36,2)) | H36: =IF(E36="","",E36+G36) | J36: =IF(A36="","",DATE(YEAR(A36),MONTH(A36),1))
F37: =IF(A37="","",Settings!$B$4) | G37: =IF(E37="","",ROUND(E37*F37,2)) | H37: =IF(E37="","",E37+G37) | J37: =IF(A37="","",DATE(YEAR(A37),MONTH(A37),1))
F38: =IF(A38="","",Settings!$B$4) | G38: =IF(E38="","",ROUND(E38*F38,2)) | H38: =IF(E38="","",E38+G38) | J38: =IF(A38="","",DATE(YEAR(A38),MONTH(A38),1))
F39: =IF(A39="","",Settings!$B$4) | G39: =IF(E39="","",ROUND(E39*F39,2)) | H39: =IF(E39="","",E39+G39) | J39: =IF(A39="","",DATE(YEAR(A39),MONTH(A39),1))
... F47: =IF(A47="","",Settings!$B$4) | G47: =IF(E47="","",ROUND(E47*F47,2)) | H47: =IF(E47="","",E47+G47) | J47: =IF(A47="","",DATE(YEAR(A47),MONTH(A47),1))
A49: March 2026 / เดือน Mar
A50: วันที่ | B50: เลขที่ใบกำกับ | C50: ลูกค้า | D50: รายละเอียด | E50: ยอดก่อน VAT | F50: อัตรา VAT | G50: ภาษีขาย | H50: ยอดรวม | I50: รับเงินแล้ว? | J50: เดือน | K50: หมายเหตุ
F51: =IF(A51="","",Settings!$B$4) | G51: =IF(E51="","",ROUND(E51*F51,2)) | H51: =IF(E51="","",E51+G51) | J51: =IF(A51="","",DATE(YEAR(A51),MONTH(A51),1))
F52: =IF(A52="","",Settings!$B$4) | G52: =IF(E52="","",ROUND(E52*F52,2)) | H52: =IF(E52="","",E52+G52) | J52: =IF(A52="","",DATE(YEAR(A52),MONTH(A52),1))
F53: =IF(A53="","",Settings!$B$4) | G53: =IF(E53="","",ROUND(E53*F53,2)) | H53: =IF(E53="","",E53+G53) | J53: =IF(A53="","",DATE(YEAR(A53),MONTH(A53),1))
F54: =IF(A54="","",Settings!$B$4) | G54: =IF(E54="","",ROUND(E54*F54,2)) | H54: =IF(E54="","",E54+G54) | J54: =IF(A54="","",DATE(YEAR(A54),MONTH(A54),1))
F55: =IF(A55="","",Settings!$B$4) | G55: =IF(E55="","",ROUND(E55*F55,2)) | H55: =IF(E55="","",E55+G55) | J55: =IF(A55="","",DATE(YEAR(A55),MONTH(A55),1))
F56: =IF(A56="","",Settings!$B$4) | G56: =IF(E56="","",ROUND(E56*F56,2)) | H56: =IF(E56="","",E56+G56) | J56: =IF(A56="","",DATE(YEAR(A56),MONTH(A56),1))
F57: =IF(A57="","",Settings!$B$4) | G57: =IF(E57="","",ROUND(E57*F57,2)) | H57: =IF(E57="","",E57+G57) | J57: =IF(A57="","",DATE(YEAR(A57),MONTH(A57),1))
...

Sheet Expenses
A1: ตารางค่าใช้จ่าย / ภาษีซื้อ
A3: วันที่ | B3: เลขที่บิล/ใบกำกับ | C3: ผู้ขาย | D3: รายละเอียด | E3: หมวด | F3: ยอดก่อน VAT | G3: อัตรา VAT | H3: ภาษีซื้อ | I3: ยอดรวม | J3: ขอคืน VAT ได้? | K3: เดือน | L3: ไฟล์บิล | M3: OCR Confidence | N3: หมายเหตุ | O3: ประเภทเอกสาร
A4: 46192 | B4: DEMO-LINE-20260619 | C4: Demo Supplier from LINE | D4: Demo receipt imported from LINE OCR | E4: Other | F4: 1000 | G4: 0.07 | H4: =IF(F4="","",IF(J4="Yes",ROUND(F4*G4,2),0)) | I4: =IF(F4="","",F4+ROUND(F4*G4,2)) | J4: Yes | K4: =IF(A4="","",DATE(YEAR(A4),MONTH(A4),1)) | L4: demo://line-receipt-image.jpg | M4: 0.95 | N4: Demo OCR text: subtotal 1000.0, VAT 70.0, total 1070.0
A5: 44008 | B5: - | C5: บริษัท สุจิโรจน์ จำกัด | D5: LINE receipt OCR | E5: อื่น ๆ | F5: 4037.38 | G5: 0.07 | H5: =IF(F5="","",IF(J5="Yes",ROUND(F5*G5,2),0)) | I5: =IF(F5="","",F5+ROUND(F5*G5,2)) | J5: Yes | K5: =IF(A5="","",DATE(YEAR(A5),MONTH(A5),1)) | L5: C:\Users\HP\Documents\Codex\2026-06-19\excel-vat-excel\outputs\line_uploaded_receipts\20260620_104332_619239839748849893_1ccac376.jpg | M5: 0.8 | N5: ะ , 7 We ล ย ค LR 0++- ๐ 0 ค ุ ณ กั ณ ฐิ ก า ท ุ ว ิ ชา น น ท ์ (0358) ท เมี่ ธั ญ ชน ก เต ชะ ด ี 0 ๕600564 ว ร เถ ม 2569 - z 5 x 2 ณั ง | า 180 ขึ ้ น 2 | - wream ต ั อ ท ร า ย + อ ุ ป ก ร ณ์ 9: | 3 ๕ 600 ขึ้น 120.00 4320.00 | O5: บิล/ใบเสร็จ
A6: 42547 | B6: - | C6: การไฟฟ้า | D6: LINE receipt OCR | E6: อื่น ๆ | F6: 2182.33 | G6: 0.07 | H6: =IF(F6="","",IF(J6="Yes",ROUND(F6*G6,2),0)) | I6: =IF(F6="","",F6+ROUND(F6*G6,2)) | J6: Yes | K6: =IF(A6="","",DATE(YEAR(A6),MONTH(A6),1)) | L6: C:\Users\HP\Documents\Codex\2026-06-19\excel-vat-excel\outputs\line_uploaded_receipts\20260620_105926_619241439607390655_9dd8c1b6.jpg | M6: 1 | N6: เล | | ก า ร เฟ ฟ้า ศา บ า ชะ อ จํา น า ง น พ ส ม บ ู ร ณ์ เร้ ไฟ ฟ้า ส ลุ 99/53 ถุ น ร า ชิ ป a. ป) ม ป ร ะ จ ั า เตือน, JCHANO36 020004022945 6300116261 000011167534 06/2569 1125 0.0000 16/06/6812:19:33 16/06/69 12:19:39 os Grameen A Version §.91.050 สู 1 จ “ว ดิ น Gry 1,998.15 64.260 62.690 1.63 24.62 18538.000 เต ง 5000 603.00 0.1623 81.64 2,104.41 —H3+ & 2,251.72 2,251.72 ฉิ ] [eee ท il ge 16/04/63 17/03/68_ 14/02/68 TT/01/88-17712768 by i 5 - แก ้ ก ร ะ แต ไฟ ฟ้า บ ั ต ชั ง 032-4 ท ป๊ 1 03 | O6: ใบกำกับภาษี
A7: 38164 | B7: 150302 | C7: ใบ แจ ้ ง ห น ี ้ ค ่ า น ้ า ป ร ะ ป า | D7: LINE receipt OCR | E7: อื่น ๆ | F7: 33 | G7: 0.07 | H7: =IF(F7="","",IF(J7="Yes",ROUND(F7*G7,2),0)) | I7: =IF(F7="","",F7+ROUND(F7*G7,2)) | J7: Yes | K7: =IF(A7="","",DATE(YEAR(A7),MONTH(A7),1)) | L7: C:\Users\HP\Documents\Codex\2026-06-19\excel-vat-excel\outputs\line_uploaded_receipts\20260620_112355_619243903895470345_e635d6a8.jpg | M7: 1 | N7: ใบ แจ ้ ง ห น ี ้ ค ่ า น ้ า ป ร ะ ป า ค ่ า ขยะ แล ะ ค ่ า บ ํ า บ ั ด น ํ า เส ี ย ก อ ง ก า ร ป ร ะ ป า เท ศ บ า ล เม ื อ ง ชะ อ ํ า ‘Municipality Waterworks Authority Cha-Am 503 ถ . เ พ ชร เก ษ ม ต ํ า บ ล ขะ อ ํ า อ ํ า เภ อ ซะ อ ํ า เพ ชร บ ุ ร ี 76120 .503 Phet Kasem Rd., Cha-am, Cha-am, Phetchaburi 76120 เล ข ป ร ะ จ ้ า ต ั ว ผู ้ เส ี ย ภา ษี / โ ล ID : 0994000541872 ้ า ป ร ะ จ ํ า เล ่ ม ท ี ่ เล ข ท ี ่ ใบ เส ร ็ จ เข ต เล ข ท ี ่ ผู ้ ใช ้ น ้ า 2 ท 20 69-4142| 3 | 94 ว ซื ่ อ ผู้ | O7: ใบเสร็จ
G8: =IF(A8="","",Settings!$B$4) | H8: =IF(F8="","",IF(J8="Yes",ROUND(F8*G8,2),0)) | I8: =IF(F8="","",F8+ROUND(F8*G8,2)) | K8: =IF(A8="","",DATE(YEAR(A8),MONTH(A8),1))
G9: =IF(A9="","",Settings!$B$4) | H9: =IF(F9="","",IF(J9="Yes",ROUND(F9*G9,2),0)) | I9: =IF(F9="","",F9+ROUND(F9*G9,2)) | K9: =IF(A9="","",DATE(YEAR(A9),MONTH(A9),1))
G10: =IF(A10="","",Settings!$B$4) | H10: =IF(F10="","",IF(J10="Yes",ROUND(F10*G10,2),0)) | I10: =IF(F10="","",F10+ROUND(F10*G10,2)) | K10: =IF(A10="","",DATE(YEAR(A10),MONTH(A10),1))
G11: =IF(A11="","",Settings!$B$4) | H11: =IF(F11="","",IF(J11="Yes",ROUND(F11*G11,2),0)) | I11: =IF(F11="","",F11+ROUND(F11*G11,2)) | K11: =IF(A11="","",DATE(YEAR(A11),MONTH(A11),1))
G12: =IF(A12="","",Settings!$B$4) | H12: =IF(F12="","",IF(J12="Yes",ROUND(F12*G12,2),0)) | I12: =IF(F12="","",F12+ROUND(F12*G12,2)) | K12: =IF(A12="","",DATE(YEAR(A12),MONTH(A12),1))
G13: =IF(A13="","",Settings!$B$4) | H13: =IF(F13="","",IF(J13="Yes",ROUND(F13*G13,2),0)) | I13: =IF(F13="","",F13+ROUND(F13*G13,2)) | K13: =IF(A13="","",DATE(YEAR(A13),MONTH(A13),1))
G14: =IF(A14="","",Settings!$B$4) | H14: =IF(F14="","",IF(J14="Yes",ROUND(F14*G14,2),0)) | I14: =IF(F14="","",F14+ROUND(F14*G14,2)) | K14: =IF(A14="","",DATE(YEAR(A14),MONTH(A14),1))
G15: =IF(A15="","",Settings!$B$4) | H15: =IF(F15="","",IF(J15="Yes",ROUND(F15*G15,2),0)) | I15: =IF(F15="","",F15+ROUND(F15*G15,2)) | K15: =IF(A15="","",DATE(YEAR(A15),MONTH(A15),1))
G16: =IF(A16="","",Settings!$B$4) | H16: =IF(F16="","",IF(J16="Yes",ROUND(F16*G16,2),0)) | I16: =IF(F16="","",F16+ROUND(F16*G16,2)) | K16: =IF(A16="","",DATE(YEAR(A16),MONTH(A16),1))
G17: =IF(A17="","",Settings!$B$4) | H17: =IF(F17="","",IF(J17="Yes",ROUND(F17*G17,2),0)) | I17: =IF(F17="","",F17+ROUND(F17*G17,2)) | K17: =IF(A17="","",DATE(YEAR(A17),MONTH(A17),1))
G18: =IF(A18="","",Settings!$B$4) | H18: =IF(F18="","",IF(J18="Yes",ROUND(F18*G18,2),0)) | I18: =IF(F18="","",F18+ROUND(F18*G18,2)) | K18: =IF(A18="","",DATE(YEAR(A18),MONTH(A18),1))
G19: =IF(A19="","",Settings!$B$4) | H19: =IF(F19="","",IF(J19="Yes",ROUND(F19*G19,2),0)) | I19: =IF(F19="","",F19+ROUND(F19*G19,2)) | K19: =IF(A19="","",DATE(YEAR(A19),MONTH(A19),1))
... G303: =IF(A303="","",Settings!$B$4) | H303: =IF(F303="","",IF(J303="Yes",ROUND(F303*G303,2),0)) | I303: =IF(F303="","",F303+ROUND(F303*G303,2)) | K303: =IF(A303="","",DATE(YEAR(A303),MONTH(A303),1))

Sheet Expenses_12M
A1: Expense Entry by Month - บันทึกค่าใช้จ่ายรายรายการครบ 12 เดือน
A3: January 2026 / เดือน Jan
A4: วันที่ | B4: เลขที่บิล/ใบกำกับ | C4: ผู้ขาย | D4: รายละเอียด | E4: หมวด | F4: ยอดก่อน VAT | G4: อัตรา VAT | H4: ภาษีซื้อ | I4: ยอดรวม | J4: ขอคืน VAT ได้? | K4: เดือน | L4: ไฟล์บิล | M4: OCR Confidence | N4: หมายเหตุ
G5: =IF(A5="","",Settings!$B$4) | H5: =IF(F5="","",IF(J5="Yes",ROUND(F5*G5,2),0)) | I5: =IF(F5="","",F5+ROUND(F5*G5,2)) | K5: =IF(A5="","",DATE(YEAR(A5),MONTH(A5),1))
G6: =IF(A6="","",Settings!$B$4) | H6: =IF(F6="","",IF(J6="Yes",ROUND(F6*G6,2),0)) | I6: =IF(F6="","",F6+ROUND(F6*G6,2)) | K6: =IF(A6="","",DATE(YEAR(A6),MONTH(A6),1))
G7: =IF(A7="","",Settings!$B$4) | H7: =IF(F7="","",IF(J7="Yes",ROUND(F7*G7,2),0)) | I7: =IF(F7="","",F7+ROUND(F7*G7,2)) | K7: =IF(A7="","",DATE(YEAR(A7),MONTH(A7),1))
G8: =IF(A8="","",Settings!$B$4) | H8: =IF(F8="","",IF(J8="Yes",ROUND(F8*G8,2),0)) | I8: =IF(F8="","",F8+ROUND(F8*G8,2)) | K8: =IF(A8="","",DATE(YEAR(A8),MONTH(A8),1))
G9: =IF(A9="","",Settings!$B$4) | H9: =IF(F9="","",IF(J9="Yes",ROUND(F9*G9,2),0)) | I9: =IF(F9="","",F9+ROUND(F9*G9,2)) | K9: =IF(A9="","",DATE(YEAR(A9),MONTH(A9),1))
G10: =IF(A10="","",Settings!$B$4) | H10: =IF(F10="","",IF(J10="Yes",ROUND(F10*G10,2),0)) | I10: =IF(F10="","",F10+ROUND(F10*G10,2)) | K10: =IF(A10="","",DATE(YEAR(A10),MONTH(A10),1))
G11: =IF(A11="","",Settings!$B$4) | H11: =IF(F11="","",IF(J11="Yes",ROUND(F11*G11,2),0)) | I11: =IF(F11="","",F11+ROUND(F11*G11,2)) | K11: =IF(A11="","",DATE(YEAR(A11),MONTH(A11),1))
G12: =IF(A12="","",Settings!$B$4) | H12: =IF(F12="","",IF(J12="Yes",ROUND(F12*G12,2),0)) | I12: =IF(F12="","",F12+ROUND(F12*G12,2)) | K12: =IF(A12="","",DATE(YEAR(A12),MONTH(A12),1))
G13: =IF(A13="","",Settings!$B$4) | H13: =IF(F13="","",IF(J13="Yes",ROUND(F13*G13,2),0)) | I13: =IF(F13="","",F13+ROUND(F13*G13,2)) | K13: =IF(A13="","",DATE(YEAR(A13),MONTH(A13),1))
G14: =IF(A14="","",Settings!$B$4) | H14: =IF(F14="","",IF(J14="Yes",ROUND(F14*G14,2),0)) | I14: =IF(F14="","",F14+ROUND(F14*G14,2)) | K14: =IF(A14="","",DATE(YEAR(A14),MONTH(A14),1))
G15: =IF(A15="","",Settings!$B$4) | H15: =IF(F15="","",IF(J15="Yes",ROUND(F15*G15,2),0)) | I15: =IF(F15="","",F15+ROUND(F15*G15,2)) | K15: =IF(A15="","",DATE(YEAR(A15),MONTH(A15),1))
G16: =IF(A16="","",Settings!$B$4) | H16: =IF(F16="","",IF(J16="Yes",ROUND(F16*G16,2),0)) | I16: =IF(F16="","",F16+ROUND(F16*G16,2)) | K16: =IF(A16="","",DATE(YEAR(A16),MONTH(A16),1))
... G24: =IF(A24="","",Settings!$B$4) | H24: =IF(F24="","",IF(J24="Yes",ROUND(F24*G24,2),0)) | I24: =IF(F24="","",F24+ROUND(F24*G24,2)) | K24: =IF(A24="","",DATE(YEAR(A24),MONTH(A24),1))
A26: February 2026 / เดือน Feb
A27: วันที่ | B27: เลขที่บิล/ใบกำกับ | C27: ผู้ขาย | D27: รายละเอียด | E27: หมวด | F27: ยอดก่อน VAT | G27: อัตรา VAT | H27: ภาษีซื้อ | I27: ยอดรวม | J27: ขอคืน VAT ได้? | K27: เดือน | L27: ไฟล์บิล | M27: OCR Confidence | N27: หมายเหตุ
G28: =IF(A28="","",Settings!$B$4) | H28: =IF(F28="","",IF(J28="Yes",ROUND(F28*G28,2),0)) | I28: =IF(F28="","",F28+ROUND(F28*G28,2)) | K28: =IF(A28="","",DATE(YEAR(A28),MONTH(A28),1))
G29: =IF(A29="","",Settings!$B$4) | H29: =IF(F29="","",IF(J29="Yes",ROUND(F29*G29,2),0)) | I29: =IF(F29="","",F29+ROUND(F29*G29,2)) | K29: =IF(A29="","",DATE(YEAR(A29),MONTH(A29),1))
G30: =IF(A30="","",Settings!$B$4) | H30: =IF(F30="","",IF(J30="Yes",ROUND(F30*G30,2),0)) | I30: =IF(F30="","",F30+ROUND(F30*G30,2)) | K30: =IF(A30="","",DATE(YEAR(A30),MONTH(A30),1))
G31: =IF(A31="","",Settings!$B$4) | H31: =IF(F31="","",IF(J31="Yes",ROUND(F31*G31,2),0)) | I31: =IF(F31="","",F31+ROUND(F31*G31,2)) | K31: =IF(A31="","",DATE(YEAR(A31),MONTH(A31),1))
G32: =IF(A32="","",Settings!$B$4) | H32: =IF(F32="","",IF(J32="Yes",ROUND(F32*G32,2),0)) | I32: =IF(F32="","",F32+ROUND(F32*G32,2)) | K32: =IF(A32="","",DATE(YEAR(A32),MONTH(A32),1))
G33: =IF(A33="","",Settings!$B$4) | H33: =IF(F33="","",IF(J33="Yes",ROUND(F33*G33,2),0)) | I33: =IF(F33="","",F33+ROUND(F33*G33,2)) | K33: =IF(A33="","",DATE(YEAR(A33),MONTH(A33),1))
G34: =IF(A34="","",Settings!$B$4) | H34: =IF(F34="","",IF(J34="Yes",ROUND(F34*G34,2),0)) | I34: =IF(F34="","",F34+ROUND(F34*G34,2)) | K34: =IF(A34="","",DATE(YEAR(A34),MONTH(A34),1))
G35: =IF(A35="","",Settings!$B$4) | H35: =IF(F35="","",IF(J35="Yes",ROUND(F35*G35,2),0)) | I35: =IF(F35="","",F35+ROUND(F35*G35,2)) | K35: =IF(A35="","",DATE(YEAR(A35),MONTH(A35),1))
G36: =IF(A36="","",Settings!$B$4) | H36: =IF(F36="","",IF(J36="Yes",ROUND(F36*G36,2),0)) | I36: =IF(F36="","",F36+ROUND(F36*G36,2)) | K36: =IF(A36="","",DATE(YEAR(A36),MONTH(A36),1))
G37: =IF(A37="","",Settings!$B$4) | H37: =IF(F37="","",IF(J37="Yes",ROUND(F37*G37,2),0)) | I37: =IF(F37="","",F37+ROUND(F37*G37,2)) | K37: =IF(A37="","",DATE(YEAR(A37),MONTH(A37),1))
G38: =IF(A38="","",Settings!$B$4) | H38: =IF(F38="","",IF(J38="Yes",ROUND(F38*G38,2),0)) | I38: =IF(F38="","",F38+ROUND(F38*G38,2)) | K38: =IF(A38="","",DATE(YEAR(A38),MONTH(A38),1))
G39: =IF(A39="","",Settings!$B$4) | H39: =IF(F39="","",IF(J39="Yes",ROUND(F39*G39,2),0)) | I39: =IF(F39="","",F39+ROUND(F39*G39,2)) | K39: =IF(A39="","",DATE(YEAR(A39),MONTH(A39),1))
... G47: =IF(A47="","",Settings!$B$4) | H47: =IF(F47="","",IF(J47="Yes",ROUND(F47*G47,2),0)) | I47: =IF(F47="","",F47+ROUND(F47*G47,2)) | K47: =IF(A47="","",DATE(YEAR(A47),MONTH(A47),1))
A49: March 2026 / เดือน Mar
A50: วันที่ | B50: เลขที่บิล/ใบกำกับ | C50: ผู้ขาย | D50: รายละเอียด | E50: หมวด | F50: ยอดก่อน VAT | G50: อัตรา VAT | H50: ภาษีซื้อ | I50: ยอดรวม | J50: ขอคืน VAT ได้? | K50: เดือน | L50: ไฟล์บิล | M50: OCR Confidence | N50: หมายเหตุ
G51: =IF(A51="","",Settings!$B$4) | H51: =IF(F51="","",IF(J51="Yes",ROUND(F51*G51,2),0)) | I51: =IF(F51="","",F51+ROUND(F51*G51,2)) | K51: =IF(A51="","",DATE(YEAR(A51),MONTH(A51),1))
G52: =IF(A52="","",Settings!$B$4) | H52: =IF(F52="","",IF(J52="Yes",ROUND(F52*G52,2),0)) | I52: =IF(F52="","",F52+ROUND(F52*G52,2)) | K52: =IF(A52="","",DATE(YEAR(A52),MONTH(A52),1))
G53: =IF(A53="","",Settings!$B$4) | H53: =IF(F53="","",IF(J53="Yes",ROUND(F53*G53,2),0)) | I53: =IF(F53="","",F53+ROUND(F53*G53,2)) | K53: =IF(A53="","",DATE(YEAR(A53),MONTH(A53),1))
G54: =IF(A54="","",Settings!$B$4) | H54: =IF(F54="","",IF(J54="Yes",ROUND(F54*G54,2),0)) | I54: =IF(F54="","",F54+ROUND(F54*G54,2)) | K54: =IF(A54="","",DATE(YEAR(A54),MONTH(A54),1))
G55: =IF(A55="","",Settings!$B$4) | H55: =IF(F55="","",IF(J55="Yes",ROUND(F55*G55,2),0)) | I55: =IF(F55="","",F55+ROUND(F55*G55,2)) | K55: =IF(A55="","",DATE(YEAR(A55),MONTH(A55),1))
G56: =IF(A56="","",Settings!$B$4) | H56: =IF(F56="","",IF(J56="Yes",ROUND(F56*G56,2),0)) | I56: =IF(F56="","",F56+ROUND(F56*G56,2)) | K56: =IF(A56="","",DATE(YEAR(A56),MONTH(A56),1))
G57: =IF(A57="","",Settings!$B$4) | H57: =IF(F57="","",IF(J57="Yes",ROUND(F57*G57,2),0)) | I57: =IF(F57="","",F57+ROUND(F57*G57,2)) | K57: =IF(A57="","",DATE(YEAR(A57),MONTH(A57),1))
...

Sheet Monthly_VAT
A1: สรุป VAT รายเดือน
A3: เดือน | B3: รายรับก่อน VAT | C3: ภาษีขาย | D3: ค่าใช้จ่ายก่อน VAT | E3: ภาษีซื้อ | F3: รายรับสุทธิ | G3: VAT ต้องจ่าย/(ขอคืน) | H3: สถานะ | I3: จำนวนรายการรายรับ | J3: จำนวนรายการค่าใช้จ่าย
A4: 46023 | B4: =SUMIFS(Transactions_12M!$G$5:$G$412,Transactions_12M!$L$5:$L$412,A4,Transactions_12M!$B$5:$B$412,"Revenue") | C4: =SUMIFS(Transactions_12M!$I$5:$I$412,Transactions_12M!$L$5:$L$412,A4,Transactions_12M!$B$5:$B$412,"Revenue") | D4: =SUMIFS(Transactions_12M!$G$5:$G$412,Transactions_12M!$L$5:$L$412,A4,Transactions_12M!$B$5:$B$412,"Expense") | E4: =SUMIFS(Transactions_12M!$I$5:$I$412,Transactions_12M!$L$5:$L$412,A4,Transactions_12M!$B$5:$B$412,"Expense",Transactions_12M!$K$5:$K$412,"Yes") | F4: =B4-D4 | G4: =C4-E4 | H4: =IF(G4>0,"ต้องจ่าย",IF(G4<0,"ขอคืน/เครดิต","ไม่มี VAT สุทธิ")) | I4: =COUNTIFS(Transactions_12M!$L$5:$L$412,A4,Transactions_12M!$B$5:$B$412,"Revenue") | J4: =COUNTIFS(Transactions_12M!$L$5:$L$412,A4,Transactions_12M!$B$5:$B$412,"Expense")
A5: 46054 | B5: =SUMIFS(Transactions_12M!$G$5:$G$412,Transactions_12M!$L$5:$L$412,A5,Transactions_12M!$B$5:$B$412,"Revenue") | C5: =SUMIFS(Transactions_12M!$I$5:$I$412,Transactions_12M!$L$5:$L$412,A5,Transactions_12M!$B$5:$B$412,"Revenue") | D5: =SUMIFS(Transactions_12M!$G$5:$G$412,Transactions_12M!$L$5:$L$412,A5,Transactions_12M!$B$5:$B$412,"Expense") | E5: =SUMIFS(Transactions_12M!$I$5:$I$412,Transactions_12M!$L$5:$L$412,A5,Transactions_12M!$B$5:$B$412,"Expense",Transactions_12M!$K$5:$K$412,"Yes") | F5: =B5-D5 | G5: =C5-E5 | H5: =IF(G5>0,"ต้องจ่าย",IF(G5<0,"ขอคืน/เครดิต","ไม่มี VAT สุทธิ")) | I5: =COUNTIFS(Transactions_12M!$L$5:$L$412,A5,Transactions_12M!$B$5:$B$412,"Revenue") | J5: =COUNTIFS(Transactions_12M!$L$5:$L$412,A5,Transactions_12M!$B$5:$B$412,"Expense")
A6: 46082 | B6: =SUMIFS(Transactions_12M!$G$5:$G$412,Transactions_12M!$L$5:$L$412,A6,Transactions_12M!$B$5:$B$412,"Revenue") | C6: =SUMIFS(Transactions_12M!$I$5:$I$412,Transactions_12M!$L$5:$L$412,A6,Transactions_12M!$B$5:$B$412,"Revenue") | D6: =SUMIFS(Transactions_12M!$G$5:$G$412,Transactions_12M!$L$5:$L$412,A6,Transactions_12M!$B$5:$B$412,"Expense") | E6: =SUMIFS(Transactions_12M!$I$5:$I$412,Transactions_12M!$L$5:$L$412,A6,Transactions_12M!$B$5:$B$412,"Expense",Transactions_12M!$K$5:$K$412,"Yes") | F6: =B6-D6 | G6: =C6-E6 | H6: =IF(G6>0,"ต้องจ่าย",IF(G6<0,"ขอคืน/เครดิต","ไม่มี VAT สุทธิ")) | I6: =COUNTIFS(Transactions_12M!$L$5:$L$412,A6,Transactions_12M!$B$5:$B$412,"Revenue") | J6: =COUNTIFS(Transactions_12M!$L$5:$L$412,A6,Transactions_12M!$B$5:$B$412,"Expense")
A7: 46113 | B7: =SUMIFS(Transactions_12M!$G$5:$G$412,Transactions_12M!$L$5:$L$412,A7,Transactions_12M!$B$5:$B$412,"Revenue") | C7: =SUMIFS(Transactions_12M!$I$5:$I$412,Transactions_12M!$L$5:$L$412,A7,Transactions_12M!$B$5:$B$412,"Revenue") | D7: =SUMIFS(Transactions_12M!$G$5:$G$412,Transactions_12M!$L$5:$L$412,A7,Transactions_12M!$B$5:$B$412,"Expense") | E7: =SUMIFS(Transactions_12M!$I$5:$I$412,Transactions_12M!$L$5:$L$412,A7,Transactions_12M!$B$5:$B$412,"Expense",Transactions_12M!$K$5:$K$412,"Yes") | F7: =B7-D7 | G7: =C7-E7 | H7: =IF(G7>0,"ต้องจ่าย",IF(G7<0,"ขอคืน/เครดิต","ไม่มี VAT สุทธิ")) | I7: =COUNTIFS(Transactions_12M!$L$5:$L$412,A7,Transactions_12M!$B$5:$B$412,"Revenue") | J7: =COUNTIFS(Transactions_12M!$L$5:$L$412,A7,Transactions_12M!$B$5:$B$412,"Expense")
A8: 46143 | B8: =SUMIFS(Transactions_12M!$G$5:$G$412,Transactions_12M!$L$5:$L$412,A8,Transactions_12M!$B$5:$B$412,"Revenue") | C8: =SUMIFS(Transactions_12M!$I$5:$I$412,Transactions_12M!$L$5:$L$412,A8,Transactions_12M!$B$5:$B$412,"Revenue") | D8: =SUMIFS(Transactions_12M!$G$5:$G$412,Transactions_12M!$L$5:$L$412,A8,Transactions_12M!$B$5:$B$412,"Expense") | E8: =SUMIFS(Transactions_12M!$I$5:$I$412,Transactions_12M!$L$5:$L$412,A8,Transactions_12M!$B$5:$B$412,"Expense",Transactions_12M!$K$5:$K$412,"Yes") | F8: =B8-D8 | G8: =C8-E8 | H8: =IF(G8>0,"ต้องจ่าย",IF(G8<0,"ขอคืน/เครดิต","ไม่มี VAT สุทธิ")) | I8: =COUNTIFS(Transactions_12M!$L$5:$L$412,A8,Transactions_12M!$B$5:$B$412,"Revenue") | J8: =COUNTIFS(Transactions_12M!$L$5:$L$412,A8,Transactions_12M!$B$5:$B$412,"Expense")
A9: 46174 | B9: =SUMIFS(Transactions_12M!$G$5:$G$412,Transactions_12M!$L$5:$L$412,A9,Transactions_12M!$B$5:$B$412,"Revenue") | C9: =SUMIFS(Transactions_12M!$I$5:$I$412,Transactions_12M!$L$5:$L$412,A9,Transactions_12M!$B$5:$B$412,"Revenue") | D9: =SUMIFS(Transactions_12M!$G$5:$G$412,Transactions_12M!$L$5:$L$412,A9,Transactions_12M!$B$5:$B$412,"Expense") | E9: =SUMIFS(Transactions_12M!$I$5:$I$412,Transactions_12M!$L$5:$L$412,A9,Transactions_12M!$B$5:$B$412,"Expense",Transactions_12M!$K$5:$K$412,"Yes") | F9: =B9-D9 | G9: =C9-E9 | H9: =IF(G9>0,"ต้องจ่าย",IF(G9<0,"ขอคืน/เครดิต","ไม่มี VAT สุทธิ")) | I9: =COUNTIFS(Transactions_12M!$L$5:$L$412,A9,Transactions_12M!$B$5:$B$412,"Revenue") | J9: =COUNTIFS(Transactions_12M!$L$5:$L$412,A9,Transactions_12M!$B$5:$B$412,"Expense")
A10: 46204 | B10: =SUMIFS(Transactions_12M!$G$5:$G$412,Transactions_12M!$L$5:$L$412,A10,Transactions_12M!$B$5:$B$412,"Revenue") | C10: =SUMIFS(Transactions_12M!$I$5:$I$412,Transactions_12M!$L$5:$L$412,A10,Transactions_12M!$B$5:$B$412,"Revenue") | D10: =SUMIFS(Transactions_12M!$G$5:$G$412,Transactions_12M!$L$5:$L$412,A10,Transactions_12M!$B$5:$B$412,"Expense") | E10: =SUMIFS(Transactions_12M!$I$5:$I$412,Transactions_12M!$L$5:$L$412,A10,Transactions_12M!$B$5:$B$412,"Expense",Transactions_12M!$K$5:$K$412,"Yes") | F10: =B10-D10 | G10: =C10-E10 | H10: =IF(G10>0,"ต้องจ่าย",IF(G10<0,"ขอคืน/เครดิต","ไม่มี VAT สุทธิ")) | I10: =COUNTIFS(Transactions_12M!$L$5:$L$412,A10,Transactions_12M!$B$5:$B$412,"Revenue") | J10: =COUNTIFS(Transactions_12M!$L$5:$L$412,A10,Transactions_12M!$B$5:$B$412,"Expense")
A11: 46235 | B11: =SUMIFS(Transactions_12M!$G$5:$G$412,Transactions_12M!$L$5:$L$412,A11,Transactions_12M!$B$5:$B$412,"Revenue") | C11: =SUMIFS(Transactions_12M!$I$5:$I$412,Transactions_12M!$L$5:$L$412,A11,Transactions_12M!$B$5:$B$412,"Revenue") | D11: =SUMIFS(Transactions_12M!$G$5:$G$412,Transactions_12M!$L$5:$L$412,A11,Transactions_12M!$B$5:$B$412,"Expense") | E11: =SUMIFS(Transactions_12M!$I$5:$I$412,Transactions_12M!$L$5:$L$412,A11,Transactions_12M!$B$5:$B$412,"Expense",Transactions_12M!$K$5:$K$412,"Yes") | F11: =B11-D11 | G11: =C11-E11 | H11: =IF(G11>0,"ต้องจ่าย",IF(G11<0,"ขอคืน/เครดิต","ไม่มี VAT สุทธิ")) | I11: =COUNTIFS(Transactions_12M!$L$5:$L$412,A11,Transactions_12M!$B$5:$B$412,"Revenue") | J11: =COUNTIFS(Transactions_12M!$L$5:$L$412,A11,Transactions_12M!$B$5:$B$412,"Expense")
A12: 46266 | B12: =SUMIFS(Transactions_12M!$G$5:$G$412,Transactions_12M!$L$5:$L$412,A12,Transactions_12M!$B$5:$B$412,"Revenue") | C12: =SUMIFS(Transactions_12M!$I$5:$I$412,Transactions_12M!$L$5:$L$412,A12,Transactions_12M!$B$5:$B$412,"Revenue") | D12: =SUMIFS(Transactions_12M!$G$5:$G$412,Transactions_12M!$L$5:$L$412,A12,Transactions_12M!$B$5:$B$412,"Expense") | E12: =SUMIFS(Transactions_12M!$I$5:$I$412,Transactions_12M!$L$5:$L$412,A12,Transactions_12M!$B$5:$B$412,"Expense",Transactions_12M!$K$5:$K$412,"Yes") | F12: =B12-D12 | G12: =C12-E12 | H12: =IF(G12>0,"ต้องจ่าย",IF(G12<0,"ขอคืน/เครดิต","ไม่มี VAT สุทธิ")) | I12: =COUNTIFS(Transactions_12M!$L$5:$L$412,A12,Transactions_12M!$B$5:$B$412,"Revenue") | J12: =COUNTIFS(Transactions_12M!$L$5:$L$412,A12,Transactions_12M!$B$5:$B$412,"Expense")
A13: 46296 | B13: =SUMIFS(Transactions_12M!$G$5:$G$412,Transactions_12M!$L$5:$L$412,A13,Transactions_12M!$B$5:$B$412,"Revenue") | C13: =SUMIFS(Transactions_12M!$I$5:$I$412,Transactions_12M!$L$5:$L$412,A13,Transactions_12M!$B$5:$B$412,"Revenue") | D13: =SUMIFS(Transactions_12M!$G$5:$G$412,Transactions_12M!$L$5:$L$412,A13,Transactions_12M!$B$5:$B$412,"Expense") | E13: =SUMIFS(Transactions_12M!$I$5:$I$412,Transactions_12M!$L$5:$L$412,A13,Transactions_12M!$B$5:$B$412,"Expense",Transactions_12M!$K$5:$K$412,"Yes") | F13: =B13-D13 | G13: =C13-E13 | H13: =IF(G13>0,"ต้องจ่าย",IF(G13<0,"ขอคืน/เครดิต","ไม่มี VAT สุทธิ")) | I13: =COUNTIFS(Transactions_12M!$L$5:$L$412,A13,Transactions_12M!$B$5:$B$412,"Revenue") | J13: =COUNTIFS(Transactions_12M!$L$5:$L$412,A13,Transactions_12M!$B$5:$B$412,"Expense")
A14: 46327 | B14: =SUMIFS(Transactions_12M!$G$5:$G$412,Transactions_12M!$L$5:$L$412,A14,Transactions_12M!$B$5:$B$412,"Revenue") | C14: =SUMIFS(Transactions_12M!$I$5:$I$412,Transactions_12M!$L$5:$L$412,A14,Transactions_12M!$B$5:$B$412,"Revenue") | D14: =SUMIFS(Transactions_12M!$G$5:$G$412,Transactions_12M!$L$5:$L$412,A14,Transactions_12M!$B$5:$B$412,"Expense") | E14: =SUMIFS(Transactions_12M!$I$5:$I$412,Transactions_12M!$L$5:$L$412,A14,Transactions_12M!$B$5:$B$412,"Expense",Transactions_12M!$K$5:$K$412,"Yes") | F14: =B14-D14 | G14: =C14-E14 | H14: =IF(G14>0,"ต้องจ่าย",IF(G14<0,"ขอคืน/เครดิต","ไม่มี VAT สุทธิ")) | I14: =COUNTIFS(Transactions_12M!$L$5:$L$412,A14,Transactions_12M!$B$5:$B$412,"Revenue") | J14: =COUNTIFS(Transactions_12M!$L$5:$L$412,A14,Transactions_12M!$B$5:$B$412,"Expense")
A15: 46357 | B15: =SUMIFS(Transactions_12M!$G$5:$G$412,Transactions_12M!$L$5:$L$412,A15,Transactions_12M!$B$5:$B$412,"Revenue") | C15: =SUMIFS(Transactions_12M!$I$5:$I$412,Transactions_12M!$L$5:$L$412,A15,Transactions_12M!$B$5:$B$412,"Revenue") | D15: =SUMIFS(Transactions_12M!$G$5:$G$412,Transactions_12M!$L$5:$L$412,A15,Transactions_12M!$B$5:$B$412,"Expense") | E15: =SUMIFS(Transactions_12M!$I$5:$I$412,Transactions_12M!$L$5:$L$412,A15,Transactions_12M!$B$5:$B$412,"Expense",Transactions_12M!$K$5:$K$412,"Yes") | F15: =B15-D15 | G15: =C15-E15 | H15: =IF(G15>0,"ต้องจ่าย",IF(G15<0,"ขอคืน/เครดิต","ไม่มี VAT สุทธิ")) | I15: =COUNTIFS(Transactions_12M!$L$5:$L$412,A15,Transactions_12M!$B$5:$B$412,"Revenue") | J15: =COUNTIFS(Transactions_12M!$L$5:$L$412,A15,Transactions_12M!$B$5:$B$412,"Expense")
A17: รวมทั้งปี | B17: =SUM(B4:B15) | C17: =SUM(C4:C15) | D17: =SUM(D4:D15) | E17: =SUM(E4:E15) | F17: =SUM(F4:F15) | G17: =SUM(G4:G15)

Sheet Settings
A1: ตั้งค่าและคำอธิบาย
A3: รายการ | B3: ค่า | D3: Supplier ที่สั่งประจำ | F3: ประเภทเอกสาร
A4: อัตรา VAT | B4: 0.07 | D4: บริษัทสุจิโรจน์ | F4: บิล
A5: ปีที่ใช้สรุป | B5: 2026 | D5: บริษัท ETC | F5: ใบเสร็จ
A6: สกุลเงิน | B6: THB | D6: บริษัทกานาไทย | F6: ใบกำกับภาษี
A7: สถานะตรวจสอบ | B7: กรอกข้อมูลรายรับ/ค่าใช้จ่าย แล้วดูผลใน Dashboard | D7: บริษัท SRTOYS | F7: บิล/ใบเสร็จ
A8: โฟลเดอร์บิลสแกน | B8: bills/
A9: หมายเหตุ | B9: ยอดสุทธิ = รายรับไม่รวม VAT - ค่าใช้จ่ายไม่รวม VAT
A11: หมวดค่าใช้จ่าย | B11: ใช้ใน dropdown
A12: สินค้า/วัตถุดิบ
A13: ค่าเช่า
A14: ค่าสาธารณูปโภค
A15: ค่าเดินทาง
A16: สำนักงาน
A17: บริการ
A18: อื่น ๆ
A19: ไม่มี VAT/ยกเว้น VAT
A20: ค่าใช้จ่ายประจำ
A21: ค่าไฟ
A22: ค่าน้ำ
A23: ค่าอินเตอร์เน็ต | B23: กรอกรายรับแยกเดือน เดือนละ 20 รายการ ระบบสรุปเข้า Monthly_VAT อัตโนมัติ
A24: ค่าโทรศัพท์ | B24: กรอกค่าใช้จ่ายแยกเดือน เดือนละ 20 รายการ ระบบสรุปเข้า Monthly_VAT อัตโนมัติ
A25: ค่าเช่าสำนักงาน | B25: Revenue และ Expenses เดิมยังใช้งานได้ สูตรสรุปรวมข้อมูลจากทั้งตารางเดิมและตารางรายเดือน
A27: หมวดรายรับ
A28: ร้านสาขาสี่แยกชะอำ | B28: ใช้ชีตนี้เป็นหลัก: กรอกวันที่ เลือกประเภท Revenue/Expense แล้วใส่ยอดก่อน VAT ระบบคำนวณ VAT และสรุปรายเดือนให้
A29: ร้านสาขาหน้าทะเล | B29: สรุปทีละเดือนจาก Transactions_12M อัตโนมัติ
A30: ร้านสาขาภูเก็ต | B30: ยังเก็บไว้เป็น reference แต่สูตรสรุปเวอร์ชันนี้ใช้ชีตรวม Transactions_12M เป็นหลัก
A31: ยอดขายส่งในระบบ PEAK

Sheet Import_Log
A1: ประวัติการนำเข้าบิลจาก OCR
A3: เวลา | B3: ไฟล์ | C3: สถานะ | D3: วันที่ | E3: ผู้ขาย | F3: ยอดรวม | G3: VAT | H3: ข้อความ/เหตุผล | I3: ประเภทเอกสาร
A4: 46192.567 | B4: demo://line-receipt-image.jpg | C4: Imported | D4: 46192 | E4: Demo Supplier from LINE | F4: 1070 | G4: 70 | H4: Demo import without real LINE webhook
A5: 46192.968 | B5: outputs\line_uploaded_receipts\20260619_224406_619167417423102420_dbea54d1.jpg | C5: Imported | D5: 61898 | E5: CP ALL, 7-Eleven น ิ ต ผ น า ย า ง (09703) | F5: 1669 | G5: 109.19 | H5: Reprocessed archived LINE receipt LINE user: manual-reprocess
A6: 46192.968 | B6: outputs\line_uploaded_receipts\20260619_225154_619168201724395606_95201af1.jpg | C6: Imported | D6: 46177 | E6: บ ิ ล เง ิ น ส ด | F6: 390 | G6: 25.51 | H6: Reprocessed archived LINE receipt LINE user: manual-reprocess
A7: 46192.968 | B7: outputs\line_uploaded_receipts\20260619_225720_619168749601161319_973ff84b.jpg | C7: Imported | D7: 46177 | E7: บ ิ ล เง ิ น ส ด | F7: 390 | G7: 25.51 | H7: Reprocessed archived LINE receipt LINE user: manual-reprocess
A8: 46193.001 | B8: C:\Users\HP\Documents\Codex\2026-06-19\excel-vat-excel\outputs\line_uploaded_receipts\20260620_000114_619175181683786052_2afe3a5d.jpg | C8: Imported | D8: 46177 | E8: บ ิ ล เง ิ น ส ด | F8: 390 | G8: 25.51 | H8: Imported from LINE OCR LINE user: Ud260925c43fb0823fea42224a2929393
A9: 46193.004 | B9: C:\Users\HP\Documents\Codex\2026-06-19\excel-vat-excel\outputs\line_uploaded_receipts\20260620_000621_619175697247633630_6561c610.jpg | C9: Imported | D9: 46156 | E9: บ ิ ล เง ิ น ส ด | F9: 12420 | G9: 812.52 | H9: Imported from LINE OCR LINE user: Ud260925c43fb0823fea42224a2929393
A10: 46193.03 | C10: DeletedRow | D10: 46193 | E10: Row 173 | F10: 364.49 | G10: 0 | H10: LINE Delete Row command row=173 old_doc=None old_party=บ ิ ล เง ิ น ส ด LINE user: Ud260925c43fb0823fea42224a2929393
A11: 46193.031 | C11: DeletedRow | D11: 46193 | E11: Row 172 | F11: 364.49 | G11: 0 | H11: LINE Delete Row command row=172 old_doc=None old_party=บ ิ ล เง ิ น ส ด LINE user: Ud260925c43fb0823fea42224a2929393
A12: 46193.036 | C12: DeletedRow | D12: 46193 | E12: Row 171 | F12: 364.49 | G12: 0 | H12: LINE Delete Row command row=171 old_doc=None old_party=บ ิ ล เง ิ น ส ด LINE user: Ud260925c43fb0823fea42224a2929393
A13: 46193.037 | C13: DeletedRow | D13: 46193 | E13: Row 137 | F13: 11607.48 | G13: 0 | H13: LINE Delete Row command row=137 old_doc=None old_party=บ ิ ล เง ิ น ส ด LINE user: Ud260925c43fb0823fea42224a2929393
A14: 46193.045 | C14: DeletedRow | D14: 46193 | E14: Row 170 | F14: 1559.81 | G14: 0 | H14: LINE Delete Row command row=170 old_doc=None old_party=CP ALL, 7-Eleven น ิ ต ผ น า ย า ง (09703) LINE user: Ud260925c43fb0823fea42224a2929393
A15: 46193.448 | B15: C:\Users\HP\Documents\Codex\2026-06-19\excel-vat-excel\outputs\line_uploaded_receipts\20260620_104332_619239839748849893_1ccac376.jpg | C15: Imported | D15: 44008 | E15: บริษัท สุจิโรจน์ จำกัด | F15: 4320 | G15: 282.62 | H15: Confirmed LINE OCR import LINE user: Ud260925c43fb0823fea42224a2929393 | I15: บิล/ใบเสร็จ
A16: 46193.459 | B16: C:\Users\HP\Documents\Codex\2026-06-19\excel-vat-excel\outputs\line_uploaded_receipts\20260620_105926_619241439607390655_9dd8c1b6.jpg | C16: Imported | D16: 42547 | E16: การไฟฟ้า | F16: 2335.09 | G16: 152.76 | H16: Confirmed LINE OCR import LINE user: Ud260925c43fb0823fea42224a2929393 | I16: ใบกำกับภาษี
A17: 46193.477 | B17: C:\Users\HP\Documents\Codex\2026-06-19\excel-vat-excel\outputs\line_uploaded_receipts\20260620_112355_619243903895470345_e635d6a8.jpg | C17: Imported | D17: 38164 | E17: ใบ แจ ้ ง ห น ี ้ ค ่ า น ้ า ป ร ะ ป า | F17: 35.31 | G17: 2.31 | H17: Confirmed LINE OCR import LINE user: U1da511c493a340b1573a67385e70278e | I17: ใบเสร็จ

Sheet Checks
A1: Checks
A3: Check | B3: Actual | C3: Expected | D3: Difference | E3: Status | F3: Notes
A4: ภาษีขายรวมเท่ากับรายรับ x VAT | B4: =SUM(Monthly_VAT!C4:C15) | C4: =SUMIFS(Transactions_12M!$I$5:$I$412,Transactions_12M!$B$5:$B$412,"Revenue") | D4: =B4-C4 | E4: =IF(ABS(D4)<0.01,"OK","Review") | F4: ตรวจ SUMIFS รายเดือน
A5: ภาษีซื้อรวมเท่ากับตารางค่าใช้จ่าย | B5: =SUM(Monthly_VAT!E4:E15) | C5: =SUMIFS(Transactions_12M!$I$5:$I$412,Transactions_12M!$B$5:$B$412,"Expense",Transactions_12M!$K$5:$K$412,"Yes") | D5: =B5-C5 | E5: =IF(ABS(D5)<0.01,"OK","Review") | F5: ตรวจ SUMIFS รายเดือน
A6: VAT สุทธิ | B6: =Monthly_VAT!G17 | C6: =SUM(Monthly_VAT!C4:C15)-SUM(Monthly_VAT!E4:E15) | D6: =B6-C6 | E6: =IF(ABS(D6)<0.01,"OK","Review") | F6: ภาษีขาย - ภาษีซื้อ
A7: สถานะรวม | B7: =COUNTIF(E4:E6,"OK") | C7: 3 | D7: =B7-C7 | E7: =IF(B7=C7,"OK","Review") | F7: ควรเป็น OK ทั้งหมด
